Workbook

Sheet RESOURCE
A1: HARGA SATUAN UPAH – BAHAN - ALAT Daerah : Gunungkidul
A2: NO | B2: Kode | C2: UPAH - MATERIAL - ALAT | D2: SATUAN | E2: HARGA SATUAN | F2: KETERANGAN
A3: 1 | C3: 2 | D3: 3 | E3: 4 | F3: 5
A4: I. | B4: UPAH
A5: 1 | B5: L.01 | C5: Pekerja | D5: jam | E5: 12500
A6: 2 | B6: L.02 | C6: Tukang | D6: jam | E6: 14125
A7: 3 | B7: L.03 | C7: Tukang Batu | D7: jam | E7: 18125
A8: 4 | B8: L.04 | C8: Mandor | D8: jam | E8: 25000
A9: II. | B9: MATERIAL
A10: 1 | B10: M.01 | C10: Agr. Pch Mesin 0-5 | D10: M3 | E10: 311162
A11: 2 | B11: M.02 | C11: Agr. Pch Mesin 5-10 & 10-20 | D11: M3 | E11: 311162
A12: 3 | B12: M.03 | C12: Agregat Kelas A | D12: M3 | E12: 235310
A13: 4 | B13: M.04 | C13: Agregat Kelas B | D13: M3 | E13: 192942
A14: 5 | B14: M.05 | C14: Agregat Kelas S | D14: M3 | E14: 230271
A15: 6 | B15: M.06 | C15: Air | D15: liter | E15: 14.65
A16: 7 | B16: M.07 | C16: Aspal | D16: Kg | E16: 14386.59
A17: 8 | B17: M.08 | C17: Aspal Emulsi RS-1 Anionik | D17: liter | E17: 15381
A18: 9 | B18: M.09 | C18: Bahan Timbunan Biasa | D18: M3 | E18: 93750
A19: 10 | B19: M.10 | C19: Baja Tulangan | D19: Kg | E19: 22880
A20: 11 | B20: M.11 | C20: Batu Kali | D20: M3 | E20: 209444
A21: 12 | B21: M.12 | C21: Beton Fc 20 Mpa | D21: M3 | E21: 1258569
... A39: 30 | B39: M.30 | C39: Pipa Galvanis Dia. 5" | D39: Batang | E39: 74955
A40: III. | B40: ALAT
A41: 1 | B41: E.01 | C41: Air Compressor | D41: jam | E41: 122600
A42: 2 | B42: E.02 | C42: AMP | D42: jam | E42: 13086911
A43: 3 | B43: E.03 | C43: Asp. Distributor | D43: jam | E43: 520594
A44: 4 | B44: E.04 | C44: Asp. Finisher | D44: jam | E44: 631284
A45: 5 | B45: E.05 | C45: Baby Vibratory Roller | D45: jam | E45: 418100
A46: 6 | B46: E.06 | C46: Concrete Mixer | D46: jam | E46: 78700
A47: 7 | B47: E.07 | C47: Crane on Track | D47: jam | E47: 702645
A48: 8 | B48: E.08 | C48: Dump Truck | D48: jam | E48: 208300
A49: 9 | B49: E.09 | C49: Dump Truck 10 Ton | D49: jam | E49: 323000
A50: 10 | B50: E.10 | C50: Excavator | D50: jam | E50: 369000
A51: 11 | B51: E.11 | C51: Flat Bed Truck | D51: jam | E51: 265000
A52: 12 | B52: E.12 | C52: Genset | D52: jam | E52: 507800
... A72: 32 | B72: E.32 | C72: Batching Plant | D72: Jam | E72: 1314137

Sheet AHSP
A1: C.19 Pembersihan dan Pengupasan Lahan
A2: No | B2: Uraian | C2: Kode | D2: Satuan | E2: Koefisien | F2: Harga Satuan (Rp) | G2: Jumlah Harga (Rp)
A3: A | B3: Tenaga Kerja
B4: Pekerja | C4: L.01 | D4: jam | E4: 0.0319
B5: Mandor | C5: L.04 | D5: jam | E5: 0.0032
B6: Jumlah Harga Tenaga Kerja
A7: B | B7: Bahan
B8: Jumlah Harga Bahan
A9: C | B9: Peralatan
B10: Bull Dozer | C10: E.28 | D10: jam | E10: 0.0048
B11: Track Loader | C11: E.29 | D11: jam | E11: 0.0032
B12: Dump Truck | C12: E.08 | D12: jam | E12: 0.0055
B13: Jumlah Harga Alat
A14: D | B14: Jumlah Harga Tenaga Kerja, Bahan, dan Peralatan (A+B+C)
A15: E | B15: Biaya Umum dan Keuntungan 15% x D | F15: 15% x D
A16: F | B16: Harga Satuan Pekerjaan (D+E)
A17: B.1 Galian untuk Selokan Drainase dan Saluran Air
A18: No | B18: Uraian | C18: Kode | D18: Satuan | E18: Koefisien | F18: Harga Satuan (Rp) | G18: Jumlah Harga (Rp)
A19: A | B19: Tenaga Kerja
B20: Pekerja | C20: L.01 | D20: jam | E20: 0.2914
B21: Mandor | C21: L.04 | D21: jam | E21: 0.0486
B22: Jumlah Harga Tenaga Kerja
A23: B | B23: Bahan
B24: Jumlah Harga Bahan
A25: C | B25: Peralatan
B26: Mini Excavator | C26: E.15 | D26: jam | E26: 0.0486
B27: Dump Truck | C27: E.08 | D27: jam | E27: 0.1137
B28: Jumlah Harga Alat
A29: D | B29: Jumlah Harga Tenaga Kerja, Bahan, dan Peralatan (A+B+C)
A30: E | B30: Biaya Umum dan Keuntungan 15% x D | F30: 15% x D
A31: F | B31: Harga Satuan Pekerjaan (D+E)
A32: B.2 Pasangan Batu dengan Mortar
A33: No | B33: Uraian | C33: Kode | D33: Satuan | E33: Koefisien | F33: Harga Satuan (Rp) | G33: Jumlah Harga (Rp)
A34: A | B34: Tenaga Kerja
B35: Pekerja | C35: L.01 | D35: jam | E35: 1.6064
B36: Tukang Batu | C36: L.03 | D36: jam | E36: 0.6426
B37: Mandor | C37: L.04 | D37: jam | E37: 0.0803
B38: Jumlah Harga Tenaga Kerja
A39: B | B39: Bahan
B40: Batu Kali | C40: M.11 | D40: M3 | E40: 1.6114
...

Sheet RAB
A1: \\ | B1: PEMBANGUNAN JALAN
A2: ] | B2: NO | C2: URAIAN PEKERJAAN | D2: VOLUME | E2: SATUAN | F2: DURASI (Week) | G2: HARGA SATUAN (RP) | H2: JUMLAH HARGA (RP)
A3: \\\\\ | B3: 1 | C3: Umum
B4: 2 | C4: Mobilisasi | D4: 1 | E4: Ls | F4: 39 | G4: 20000000
B5: 3 | C5: Pembersihan Lahan | D5: 30000 | E5: m2 | F5: 14 | G5: =AHSP!H14
B6: 4 | C6: Manajemen dan Keselamat an Lalu Lintas | D6: 1 | E6: Ls | F6: 39 | G6: 15000000
B7: 5 | C7: Manajemen Mutu | D7: 1 | E7: Ls | F7: 39 | G7: 10000000
B8: 6 | C8: Sondir Termasuk Laporan | D8: 1 | E8: Ls | F8: 1 | G8: 5000000
B9: 7 | C9: Perkerjaan Drainase
B10: 8 | C10: Galian untuk Drainse Selokan dan Saluran Air | D10: 750 | E10: m3 | F10: 3 | G10: =AHSP!H29
B11: 9 | C11: Pasangan Batu dengan Mortar | D11: 60 | E11: m3 | F11: 1 | G11: =AHSP!H52
B12: 10 | C12: perkerjaan gorong gorong | D12: 9 | E12: unit | F12: 1 | G12: =AHSP!H77
B13: 11 | C13: Perkerjaan tanah
B14: 12 | C14: galian biasa | D14: 10500 | E14: m3 | F14: 5 | G14: =AHSP!H92
B15: 13 | C15: Timbunan Biasa | D15: 4200 | E15: m3 | F15: 3 | G15: =AHSP!H112
B16: 14 | C16: Penyiapan Badan Jalan | D16: 21000 | E16: m2 | F16: 1 | G16: =AHSP!H127
B17: 15 | C17: Pelebaran Perkerasan dan Bahu Jalan
B18: 16 | C18: Lapis Pondasi Agregat Kelas A | D18: 4200 | E18: m3 | F18: 3 | G18: =AHSP!H145
B19: 17 | C19: Lapis Pondasi Agregat Kelas S Bahu Jalan | D19: 600 | E19: m3 | F19: 2 | G19: =AHSP!H163
B20: 18 | C20: Perkerjaan struktur
B21: 19 | C21: Lapis Pondasi Agregat Kelas S Bahu Jalan | D21: 600 | E21: m3 | F21: 2 | G21: =AHSP!H163
B22: 20 | C22: Lapis Pondasi Agregat Kelas A | D22: 4200 | E22: m3 | F22: 4 | G22: =AHSP!H145
B23: 21 | C23: Lapis Fondasi Agregat Kelas B | D23: 1400 | E23: m3 | F23: 7 | G23: =AHSP!H182
B24: 22 | C24: Perkerjaan Aspal dan bahu
B25: 23 | C25: Lapis Perekat - Aspal Cair/Emulsi Rapid Setting | D25: 14000 | E25: m2 | F25: 1 | G25: =AHSP!H199
B26: 24 | C26: Laston Lapis Antara (AC- BC) | D26: 1260 | E26: m3 | F26: 2 | G26: =AHSP!H223
B27: 25 | C27: Laston Lapis Aus (AC- WC) | D27: 840 | E27: m3 | F27: 3 | G27: =AHSP!H247
B28: 26 | C28: pengecoran bahu jalan | D28: 600 | E28: m3 | F28: 7 | G28: =AHSP!H270
B29: 27 | C29: Pengembalian Kondisi dan Pekerjaan Minor
B30: 28 | C30: Marka Jalan Termoplastik | D30: 3000 | E30: m | F30: 2 | G30: =AHSP!H290
B31: 29 | C31: Residu Bitumen untuk Pekerjaan Minor | D31: 1 | E31: ls | F31: 1 | G31: 8500000
B32: 30 | C32: Rambu Jalan Tunggal | D32: 60 | E32: unit | F32: 1 | G32: =AHSP!H308
B33: 31 | C33: Patok Pengarah | D33: 120 | E33: buah | F33: 2 | G33: =AHSP!H326
B34: 32 | C34: Patok Kilometer | D34: 3 | E34: buah | F34: 1 | G34: =AHSP!H343
B35: 33 | C35: Kerb Pracetak Jenis 1 | D35: 900 | E35: m3 | F35: 2 | G35: =AHSP!H360
B36: 34 | C36: Lampu Penerangan Jalan Lengan Ganda | D36: 75 | E36: unit | F36: 3 | G36: =AHSP!H379
B37: 35 | C37: Pekerjaan Pemeliharaan Rutin
B38: 36 | C38: Pemelihar aan Rutin Bahu Jalan | D38: 1 | E38: Ls | F38: 1 | G38: 10000000
B39: 37 | C39: Pemeliharaan Rutin Saluran Air | D39: 1 | E39: Ls | F39: 1 | G39: 10000000
B40: 38 | C40: Pemeliharaan Rutin Perlengkapan Jalan | D40: 1 | E40: Ls | F40: 1 | G40: 7000000
...
